Workbook

Sheet Общий
A1: Дискретная математика — общий лист
A3: Практик | B3: ФИО | C3: TG | D3: Прод | E3: D | F3: CW | G3: Тир | H3: Экзамен | I3: Комментарий
A4: Артём | B4: Студент1.1 | D4: Да | E4: =IF(B4="","",SUMIF('Логи'!$A$4:$A$3006,B4,'Логи'!$H$4:$H$3006)) | F4: =IF(B4="","",SUMIF('CW'!$A:$A,B4,'CW'!$D:$D)) | G4: =IF(B4="","",IF(AND(E4>=55,F4>=24),"S",IF(AND(E4>=35,F4>=14),"A",IF(E4>=17,"B","Допса"))))
A5: Артём | B5: Студент1.2 | D5: Да | E5: =IF(B5="","",SUMIF('Логи'!$A$4:$A$3006,B5,'Логи'!$H$4:$H$3006)) | F5: =IF(B5="","",SUMIF('CW'!$A:$A,B5,'CW'!$D:$D)) | G5: =IF(B5="","",IF(AND(E5>=55,F5>=24),"S",IF(AND(E5>=35,F5>=14),"A",IF(E5>=17,"B","Допса"))))
A6: Артём | B6: Студент1.3 | D6: Да | E6: =IF(B6="","",SUMIF('Логи'!$A$4:$A$3006,B6,'Логи'!$H$4:$H$3006)) | F6: =IF(B6="","",SUMIF('CW'!$A:$A,B6,'CW'!$D:$D)) | G6: =IF(B6="","",IF(AND(E6>=55,F6>=24),"S",IF(AND(E6>=35,F6>=14),"A",IF(E6>=17,"B","Допса"))))
A7: Артём | B7: Студент1.4 | D7: Да | E7: =IF(B7="","",SUMIF('Логи'!$A$4:$A$3006,B7,'Логи'!$H$4:$H$3006)) | F7: =IF(B7="","",SUMIF('CW'!$A:$A,B7,'CW'!$D:$D)) | G7: =IF(B7="","",IF(AND(E7>=55,F7>=24),"S",IF(AND(E7>=35,F7>=14),"A",IF(E7>=17,"B","Допса"))))
A8: Артём | B8: Студент1.5 | D8: Да | E8: =IF(B8="","",SUMIF('Логи'!$A$4:$A$3006,B8,'Логи'!$H$4:$H$3006)) | F8: =IF(B8="","",SUMIF('CW'!$A:$A,B8,'CW'!$D:$D)) | G8: =IF(B8="","",IF(AND(E8>=55,F8>=24),"S",IF(AND(E8>=35,F8>=14),"A",IF(E8>=17,"B","Допса"))))
A9: Артём | B9: Студент1.6 | D9: Да | E9: =IF(B9="","",SUMIF('Логи'!$A$4:$A$3006,B9,'Логи'!$H$4:$H$3006)) | F9: =IF(B9="","",SUMIF('CW'!$A:$A,B9,'CW'!$D:$D)) | G9: =IF(B9="","",IF(AND(E9>=55,F9>=24),"S",IF(AND(E9>=35,F9>=14),"A",IF(E9>=17,"B","Допса"))))
A10: Артём | B10: Студент1.7 | D10: Да | E10: =IF(B10="","",SUMIF('Логи'!$A$4:$A$3006,B10,'Логи'!$H$4:$H$3006)) | F10: =IF(B10="","",SUMIF('CW'!$A:$A,B10,'CW'!$D:$D)) | G10: =IF(B10="","",IF(AND(E10>=55,F10>=24),"S",IF(AND(E10>=35,F10>=14),"A",IF(E10>=17,"B","Допса"))))
A11: Артём | B11: Студент1.8 | D11: Да | E11: =IF(B11="","",SUMIF('Логи'!$A$4:$A$3006,B11,'Логи'!$H$4:$H$3006)) | F11: =IF(B11="","",SUMIF('CW'!$A:$A,B11,'CW'!$D:$D)) | G11: =IF(B11="","",IF(AND(E11>=55,F11>=24),"S",IF(AND(E11>=35,F11>=14),"A",IF(E11>=17,"B","Допса"))))
A12: Артём | B12: Студент1.9 | D12: Да | E12: =IF(B12="","",SUMIF('Логи'!$A$4:$A$3006,B12,'Логи'!$H$4:$H$3006)) | F12: =IF(B12="","",SUMIF('CW'!$A:$A,B12,'CW'!$D:$D)) | G12: =IF(B12="","",IF(AND(E12>=55,F12>=24),"S",IF(AND(E12>=35,F12>=14),"A",IF(E12>=17,"B","Допса"))))
A13: Артём | B13: Студент1.10 | D13: Да | E13: =IF(B13="","",SUMIF('Логи'!$A$4:$A$3006,B13,'Логи'!$H$4:$H$3006)) | F13: =IF(B13="","",SUMIF('CW'!$A:$A,B13,'CW'!$D:$D)) | G13: =IF(B13="","",IF(AND(E13>=55,F13>=24),"S",IF(AND(E13>=35,F13>=14),"A",IF(E13>=17,"B","Допса"))))
A14: Артём | B14: Студент1.11 | D14: Да | E14: =IF(B14="","",SUMIF('Логи'!$A$4:$A$3006,B14,'Логи'!$H$4:$H$3006)) | F14: =IF(B14="","",SUMIF('CW'!$A:$A,B14,'CW'!$D:$D)) | G14: =IF(B14="","",IF(AND(E14>=55,F14>=24),"S",IF(AND(E14>=35,F14>=14),"A",IF(E14>=17,"B","Допса"))))
A15: Артём | B15: Студент1.12 | D15: Да | E15: =IF(B15="","",SUMIF('Логи'!$A$4:$A$3006,B15,'Логи'!$H$4:$H$3006)) | F15: =IF(B15="","",SUMIF('CW'!$A:$A,B15,'CW'!$D:$D)) | G15: =IF(B15="","",IF(AND(E15>=55,F15>=24),"S",IF(AND(E15>=35,F15>=14),"A",IF(E15>=17,"B","Допса"))))
... A93: Немат | B93: Студент3.30 | D93: Да | E93: =IF(B93="","",SUMIF('Логи'!$A$4:$A$3006,B93,'Логи'!$H$4:$H$3006)) | F93: =IF(B93="","",SUMIF('CW'!$A:$A,B93,'CW'!$D:$D)) | G93: =IF(B93="","",IF(AND(E93>=55,F93>=24),"S",IF(AND(E93>=35,F93>=14),"A",IF(E93>=17,"B","Допса"))))

Sheet CW
A1: КР-1 | K1: CW
D2: W | E2: 0.5 | F2: 0.5 | G2: 1 | H2: 1 | I2: 2
A3: Имя | B3: Попытка | C3: TG | D3: S | E3: 1 | F3: 2 | G3: 3 | H3: 4 | I3: 5
A4: Студент1.1 | D4: =IF(A4="","",SUMPRODUCT(E4:I4,E$2:I$2))
A5: Студент1.2 | D5: =IF(A5="","",SUMPRODUCT(E5:I5,E$2:I$2))
A6: Студент1.3 | D6: =IF(A6="","",SUMPRODUCT(E6:I6,E$2:I$2))
A7: Студент1.4 | D7: =IF(A7="","",SUMPRODUCT(E7:I7,E$2:I$2))
A8: Студент1.5 | D8: =IF(A8="","",SUMPRODUCT(E8:I8,E$2:I$2))
A9: Студент1.6 | D9: =IF(A9="","",SUMPRODUCT(E9:I9,E$2:I$2))
A10: Студент1.7 | D10: =IF(A10="","",SUMPRODUCT(E10:I10,E$2:I$2))
A11: Студент1.8 | D11: =IF(A11="","",SUMPRODUCT(E11:I11,E$2:I$2))
A12: Студент1.9 | D12: =IF(A12="","",SUMPRODUCT(E12:I12,E$2:I$2))
A13: Студент1.10 | D13: =IF(A13="","",SUMPRODUCT(E13:I13,E$2:I$2))
A14: Студент1.11 | D14: =IF(A14="","",SUMPRODUCT(E14:I14,E$2:I$2))
A15: Студент1.12 | D15: =IF(A15="","",SUMPRODUCT(E15:I15,E$2:I$2))
... A93: Студент3.30 | D93: =IF(A93="","",SUMPRODUCT(E93:I93,E$2:I$2))
A95: КР-2
D96: W | E96: 1 | F96: 1 | G96: 1 | H96: 1.5 | I96: 1
A97: Имя | B97: Попытка | C97: TG | D97: S | E97: 1 | F97: 2 | G97: 3 | H97: 4 | I97: 5
A98: Студент1.1 | D98: =IF(A98="","",SUMPRODUCT(E98:I98,E$96:I$96))
A99: Студент1.2 | D99: =IF(A99="","",SUMPRODUCT(E99:I99,E$96:I$96))
A100: Студент1.3 | D100: =IF(A100="","",SUMPRODUCT(E100:I100,E$96:I$96))
A101: Студент1.4 | D101: =IF(A101="","",SUMPRODUCT(E101:I101,E$96:I$96))
A102: Студент1.5 | D102: =IF(A102="","",SUMPRODUCT(E102:I102,E$96:I$96))
A103: Студент1.6 | D103: =IF(A103="","",SUMPRODUCT(E103:I103,E$96:I$96))
A104: Студент1.7 | D104: =IF(A104="","",SUMPRODUCT(E104:I104,E$96:I$96))
A105: Студент1.8 | D105: =IF(A105="","",SUMPRODUCT(E105:I105,E$96:I$96))
A106: Студент1.9 | D106: =IF(A106="","",SUMPRODUCT(E106:I106,E$96:I$96))
A107: Студент1.10 | D107: =IF(A107="","",SUMPRODUCT(E107:I107,E$96:I$96))
A108: Студент1.11 | D108: =IF(A108="","",SUMPRODUCT(E108:I108,E$96:I$96))
A109: Студент1.12 | D109: =IF(A109="","",SUMPRODUCT(E109:I109,E$96:I$96))
... A187: Студент3.30 | D187: =IF(A187="","",SUMPRODUCT(E187:I187,E$96:I$96))

Sheet Рейтинг
A1: Общий рейтинг
A3: Практик | B3: ФИО | C3: TG | D3: Прод | E3: D | F3: CW | G3: Тир | H3: Экзамен | I3: Комментарий

Sheet Логи
A1: Логи D
A3: ФИО | B3: Практик | C3: Практика | D3: Задача | E3: Номер выхода | F3: База D | G3: Коэффициент | H3: Начислено D | I3: Статус | J3: Поправка | K3: Дата
E4: =IF(A4="","",COUNTIFS($A$4:A4,A4,$I$4:I4,"<>Штраф -2",$I$4:I4,"<>ушел на базу")) | F4: =IF(E4="","",IF(E4<=3,6,IF(E4<=6,5,IF(E4<=9,4,IF(E4<=12,3,IF(E4<=15,2,0)))))) | H4: =IF(I4="Штраф -2",-2,IF(OR(F4="",G4=""),"",F4*G4+IF(J4="",0,J4)))
E5: =IF(A5="","",COUNTIFS($A$4:A5,A5,$I$4:I5,"<>Штраф -2",$I$4:I5,"<>ушел на базу")) | F5: =IF(E5="","",IF(E5<=3,6,IF(E5<=6,5,IF(E5<=9,4,IF(E5<=12,3,IF(E5<=15,2,0)))))) | H5: =IF(I5="Штраф -2",-2,IF(OR(F5="",G5=""),"",F5*G5+IF(J5="",0,J5)))
E6: =IF(A6="","",COUNTIFS($A$4:A6,A6,$I$4:I6,"<>Штраф -2",$I$4:I6,"<>ушел на базу")) | F6: =IF(E6="","",IF(E6<=3,6,IF(E6<=6,5,IF(E6<=9,4,IF(E6<=12,3,IF(E6<=15,2,0)))))) | H6: =IF(I6="Штраф -2",-2,IF(OR(F6="",G6=""),"",F6*G6+IF(J6="",0,J6)))
E7: =IF(A7="","",COUNTIFS($A$4:A7,A7,$I$4:I7,"<>Штраф -2",$I$4:I7,"<>ушел на базу")) | F7: =IF(E7="","",IF(E7<=3,6,IF(E7<=6,5,IF(E7<=9,4,IF(E7<=12,3,IF(E7<=15,2,0)))))) | H7: =IF(I7="Штраф -2",-2,IF(OR(F7="",G7=""),"",F7*G7+IF(J7="",0,J7)))
E8: =IF(A8="","",COUNTIFS($A$4:A8,A8,$I$4:I8,"<>Штраф -2",$I$4:I8,"<>ушел на базу")) | F8: =IF(E8="","",IF(E8<=3,6,IF(E8<=6,5,IF(E8<=9,4,IF(E8<=12,3,IF(E8<=15,2,0)))))) | H8: =IF(I8="Штраф -2",-2,IF(OR(F8="",G8=""),"",F8*G8+IF(J8="",0,J8)))
E9: =IF(A9="","",COUNTIFS($A$4:A9,A9,$I$4:I9,"<>Штраф -2",$I$4:I9,"<>ушел на базу")) | F9: =IF(E9="","",IF(E9<=3,6,IF(E9<=6,5,IF(E9<=9,4,IF(E9<=12,3,IF(E9<=15,2,0)))))) | H9: =IF(I9="Штраф -2",-2,IF(OR(F9="",G9=""),"",F9*G9+IF(J9="",0,J9)))
E10: =IF(A10="","",COUNTIFS($A$4:A10,A10,$I$4:I10,"<>Штраф -2",$I$4:I10,"<>ушел на базу")) | F10: =IF(E10="","",IF(E10<=3,6,IF(E10<=6,5,IF(E10<=9,4,IF(E10<=12,3,IF(E10<=15,2,0)))))) | H10: =IF(I10="Штраф -2",-2,IF(OR(F10="",G10=""),"",F10*G10+IF(J10="",0,J10)))
E11: =IF(A11="","",COUNTIFS($A$4:A11,A11,$I$4:I11,"<>Штраф -2",$I$4:I11,"<>ушел на базу")) | F11: =IF(E11="","",IF(E11<=3,6,IF(E11<=6,5,IF(E11<=9,4,IF(E11<=12,3,IF(E11<=15,2,0)))))) | H11: =IF(I11="Штраф -2",-2,IF(OR(F11="",G11=""),"",F11*G11+IF(J11="",0,J11)))
E12: =IF(A12="","",COUNTIFS($A$4:A12,A12,$I$4:I12,"<>Штраф -2",$I$4:I12,"<>ушел на базу")) | F12: =IF(E12="","",IF(E12<=3,6,IF(E12<=6,5,IF(E12<=9,4,IF(E12<=12,3,IF(E12<=15,2,0)))))) | H12: =IF(I12="Штраф -2",-2,IF(OR(F12="",G12=""),"",F12*G12+IF(J12="",0,J12)))
E13: =IF(A13="","",COUNTIFS($A$4:A13,A13,$I$4:I13,"<>Штраф -2",$I$4:I13,"<>ушел на базу")) | F13: =IF(E13="","",IF(E13<=3,6,IF(E13<=6,5,IF(E13<=9,4,IF(E13<=12,3,IF(E13<=15,2,0)))))) | H13: =IF(I13="Штраф -2",-2,IF(OR(F13="",G13=""),"",F13*G13+IF(J13="",0,J13)))
E14: =IF(A14="","",COUNTIFS($A$4:A14,A14,$I$4:I14,"<>Штраф -2",$I$4:I14,"<>ушел на базу")) | F14: =IF(E14="","",IF(E14<=3,6,IF(E14<=6,5,IF(E14<=9,4,IF(E14<=12,3,IF(E14<=15,2,0)))))) | H14: =IF(I14="Штраф -2",-2,IF(OR(F14="",G14=""),"",F14*G14+IF(J14="",0,J14)))
E15: =IF(A15="","",COUNTIFS($A$4:A15,A15,$I$4:I15,"<>Штраф -2",$I$4:I15,"<>ушел на базу")) | F15: =IF(E15="","",IF(E15<=3,6,IF(E15<=6,5,IF(E15<=9,4,IF(E15<=12,3,IF(E15<=15,2,0)))))) | H15: =IF(I15="Штраф -2",-2,IF(OR(F15="",G15=""),"",F15*G15+IF(J15="",0,J15)))
... E3006: =IF(A3006="","",COUNTIFS($A$4:A3006,A3006,$I$4:I3006,"<>Штраф -2",$I$4:I3006,"<>ушел на базу")) | F3006: =IF(E3006="","",IF(E3006<=3,6,IF(E3006<=6,5,IF(E3006<=9,4,IF(E3006<=12,3,IF(E3006<=15,2,0)))))) | H3006: =IF(I3006="Штраф -2",-2,IF(OR(F3006="",G3006=""),"",F3006*G3006+IF(J3006="",0,J3006)))

Sheet Плюсы_Артём
A1: Плюсы — Артём
A4: Практика 1 — плюсы
A5: Имя | B5: TG | C5: S | D5: Коэффициент | E5: D за практику | F5: 1.0 | G5: 2.0 | H5: 3.0 | I5: 4.0 | J5: 5.0 | K5: 6 | L5: 7 | M5: 8 | N5: 9 | O5: 10 | P5: 11 | Q5: 12 | R5: 13 | S5: 14 | T5: 15 | U5: 16 | V5: 17 | W5: 18 | X5: 19 | Y5: 20 | Z5: 21 | AA5: 22 | AB5: 23 | AC5: 24 | AD5: 25 | AE5: 26 | AF5: 27 | AG5: 28 | AH5: 29 | AI5: 30
A6: Студент1.1 | C6: =IF(A6="","",COUNTIF(F6:AI6,"+")+COUNTIF(F6:AI6,"1")) | D6: =IF(A6="","",IF(C6>2*COUNTA(F$5:AI$5)/3,1,IF(C6>=COUNTA(F$5:AI$5)/2,0.8,0.5))) | E6: =IF(A6="","",SUMIFS('Логи'!$H$4:$H$3006,'Логи'!$A$4:$A$3006,A6,'Логи'!$C$4:$C$3006,1))
A7: Студент1.2 | C7: =IF(A7="","",COUNTIF(F7:AI7,"+")+COUNTIF(F7:AI7,"1")) | D7: =IF(A7="","",IF(C7>2*COUNTA(F$5:AI$5)/3,1,IF(C7>=COUNTA(F$5:AI$5)/2,0.8,0.5))) | E7: =IF(A7="","",SUMIFS('Логи'!$H$4:$H$3006,'Логи'!$A$4:$A$3006,A7,'Логи'!$C$4:$C$3006,1))
A8: Студент1.3 | C8: =IF(A8="","",COUNTIF(F8:AI8,"+")+COUNTIF(F8:AI8,"1")) | D8: =IF(A8="","",IF(C8>2*COUNTA(F$5:AI$5)/3,1,IF(C8>=COUNTA(F$5:AI$5)/2,0.8,0.5))) | E8: =IF(A8="","",SUMIFS('Логи'!$H$4:$H$3006,'Логи'!$A$4:$A$3006,A8,'Логи'!$C$4:$C$3006,1))
A9: Студент1.4 | C9: =IF(A9="","",COUNTIF(F9:AI9,"+")+COUNTIF(F9:AI9,"1")) | D9: =IF(A9="","",IF(C9>2*COUNTA(F$5:AI$5)/3,1,IF(C9>=COUNTA(F$5:AI$5)/2,0.8,0.5))) | E9: =IF(A9="","",SUMIFS('Логи'!$H$4:$H$3006,'Логи'!$A$4:$A$3006,A9,'Логи'!$C$4:$C$3006,1))
A10: Студент1.5 | C10: =IF(A10="","",COUNTIF(F10:AI10,"+")+COUNTIF(F10:AI10,"1")) | D10: =IF(A10="","",IF(C10>2*COUNTA(F$5:AI$5)/3,1,IF(C10>=COUNTA(F$5:AI$5)/2,0.8,0.5))) | E10: =IF(A10="","",SUMIFS('Логи'!$H$4:$H$3006,'Логи'!$A$4:$A$3006,A10,'Логи'!$C$4:$C$3006,1))
A11: Студент1.6 | C11: =IF(A11="","",COUNTIF(F11:AI11,"+")+COUNTIF(F11:AI11,"1")) | D11: =IF(A11="","",IF(C11>2*COUNTA(F$5:AI$5)/3,1,IF(C11>=COUNTA(F$5:AI$5)/2,0.8,0.5))) | E11: =IF(A11="","",SUMIFS('Логи'!$H$4:$H$3006,'Логи'!$A$4:$A$3006,A11,'Логи'!$C$4:$C$3006,1))
A12: Студент1.7 | C12: =IF(A12="","",COUNTIF(F12:AI12,"+")+COUNTIF(F12:AI12,"1")) | D12: =IF(A12="","",IF(C12>2*COUNTA(F$5:AI$5)/3,1,IF(C12>=COUNTA(F$5:AI$5)/2,0.8,0.5))) | E12: =IF(A12="","",SUMIFS('Логи'!$H$4:$H$3006,'Логи'!$A$4:$A$3006,A12,'Логи'!$C$4:$C$3006,1))
A13: Студент1.8 | C13: =IF(A13="","",COUNTIF(F13:AI13,"+")+COUNTIF(F13:AI13,"1")) | D13: =IF(A13="","",IF(C13>2*COUNTA(F$5:AI$5)/3,1,IF(C13>=COUNTA(F$5:AI$5)/2,0.8,0.5))) | E13: =IF(A13="","",SUMIFS('Логи'!$H$4:$H$3006,'Логи'!$A$4:$A$3006,A13,'Логи'!$C$4:$C$3006,1))
A14: Студент1.9 | C14: =IF(A14="","",COUNTIF(F14:AI14,"+")+COUNTIF(F14:AI14,"1")) | D14: =IF(A14="","",IF(C14>2*COUNTA(F$5:AI$5)/3,1,IF(C14>=COUNTA(F$5:AI$5)/2,0.8,0.5))) | E14: =IF(A14="","",SUMIFS('Логи'!$H$4:$H$3006,'Логи'!$A$4:$A$3006,A14,'Логи'!$C$4:$C$3006,1))
A15: Студент1.10 | C15: =IF(A15="","",COUNTIF(F15:AI15,"+")+COUNTIF(F15:AI15,"1")) | D15: =IF(A15="","",IF(C15>2*COUNTA(F$5:AI$5)/3,1,IF(C15>=COUNTA(F$5:AI$5)/2,0.8,0.5))) | E15: =IF(A15="","",SUMIFS('Логи'!$H$4:$H$3006,'Логи'!$A$4:$A$3006,A15,'Логи'!$C$4:$C$3006,1))
A16: Студент1.11 | C16: =IF(A16="","",COUNTIF(F16:AI16,"+")+COUNTIF(F16:AI16,"1")) | D16: =IF(A16="","",IF(C16>2*COUNTA(F$5:AI$5)/3,1,IF(C16>=COUNTA(F$5:AI$5)/2,0.8,0.5))) | E16: =IF(A16="","",SUMIFS('Логи'!$H$4:$H$3006,'Логи'!$A$4:$A$3006,A16,'Логи'!$C$4:$C$3006,1))
A17: Студент1.12 | C17: =IF(A17="","",COUNTIF(F17:AI17,"+")+COUNTIF(F17:AI17,"1")) | D17: =IF(A17="","",IF(C17>2*COUNTA(F$5:AI$5)/3,1,IF(C17>=COUNTA(F$5:AI$5)/2,0.8,0.5))) | E17: =IF(A17="","",SUMIFS('Логи'!$H$4:$H$3006,'Логи'!$A$4:$A$3006,A17,'Логи'!$C$4:$C$3006,1))
... A35: Студент1.30 | C35: =IF(A35="","",COUNTIF(F35:AI35,"+")+COUNTIF(F35:AI35,"1")) | D35: =IF(A35="","",IF(C35>2*COUNTA(F$5:AI$5)/3,1,IF(C35>=COUNTA(F$5:AI$5)/2,0.8,0.5))) | E35: =IF(A35="","",SUMIFS('Логи'!$H$4:$H$3006,'Логи'!$A$4:$A$3006,A35,'Логи'!$C$4:$C$3006,1))
A37: Практика 1 — результаты рассказа
A38: Имя | B38: TG | F38: 1.0 | G38: 2.0 | H38: 3.0 | I38: 4.0 | J38: 5.0 | K38: 6 | L38: 7 | M38: 8 | N38: 9 | O38: 10 | P38: 11 | Q38: 12 | R38: 13 | S38: 14 | T38: 15 | U38: 16 | V38: 17 | W38: 18 | X38: 19 | Y38: 20 | Z38: 21 | AA38: 22 | AB38: 23 | AC38: 24 | AD38: 25 | AE38: 26 | AF38: 27 | AG38: 28 | AH38: 29 | AI38: 30
A39: Студент1.1
A40: Студент1.2
A41: Студент1.3
A42: Студент1.4
A43: Студент1.5
A44: Студент1.6
A45: Студент1.7
A46: Студент1.8
A47: Студент1.9
A48: Студент1.10
A49: Студент1.11
A50: Студент1.12
... A72: Практика 2 — плюсы
A73: Имя | B73: TG | C73: S | D73: Коэффициент | E73: D за практику | F73: 1.0 | G73: 2.0 | H73: 3.0 | I73: 4.0 | J73: 5.0 | K73: 6 | L73: 7 | M73: 8 | N73: 9 | O73: 10 | P73: 11 | Q73: 12 | R73: 13 | S73: 14 | T73: 15 | U73: 16 | V73: 17 | W73: 18 | X73: 19 | Y73: 20 | Z73: 21 | AA73: 22 | AB73: 23 | AC73: 24 | AD73: 25 | AE73: 26 | AF73: 27 | AG73: 28 | AH73: 29 | AI73: 30
A74: Студент1.1 | C74: =IF(A74="","",COUNTIF(F74:AI74,"+")+COUNTIF(F74:AI74,"1")) | D74: =IF(A74="","",IF(C74>2*COUNTA(F$73:AI$73)/3,1,IF(C74>=COUNTA(F$73:AI$73)/2,0.8,0.5))) | E74: =IF(A74="","",SUMIFS('Логи'!$H$4:$H$3006,'Логи'!$A$4:$A$3006,A74,'Логи'!$C$4:$C$3006,2))
A75: Студент1.2 | C75: =IF(A75="","",COUNTIF(F75:AI75,"+")+COUNTIF(F75:AI75,"1")) | D75: =IF(A75="","",IF(C75>2*COUNTA(F$73:AI$73)/3,1,IF(C75>=COUNTA(F$73:AI$73)/2,0.8,0.5))) | E75: =IF(A75="","",SUMIFS('Логи'!$H$4:$H$3006,'Логи'!$A$4:$A$3006,A75,'Логи'!$C$4:$C$3006,2))
A76: Студент1.3 | C76: =IF(A76="","",COUNTIF(F76:AI76,"+")+COUNTIF(F76:AI76,"1")) | D76: =IF(A76="","",IF(C76>2*COUNTA(F$73:AI$73)/3,1,IF(C76>=COUNTA(F$73:AI$73)/2,0.8,0.5))) | E76: =IF(A76="","",SUMIFS('Логи'!$H$4:$H$3006,'Логи'!$A$4:$A$3006,A76,'Логи'!$C$4:$C$3006,2))
A77: Студент1.4 | C77: =IF(A77="","",COUNTIF(F77:AI77,"+")+COUNTIF(F77:AI77,"1")) | D77: =IF(A77="","",IF(C77>2*COUNTA(F$73:AI$73)/3,1,IF(C77>=COUNTA(F$73:AI$73)/2,0.8,0.5))) | E77: =IF(A77="","",SUMIFS('Логи'!$H$4:$H$3006,'Логи'!$A$4:$A$3006,A77,'Логи'!$C$4:$C$3006,2))
A78: Студент1.5 | C78: =IF(A78="","",COUNTIF(F78:AI78,"+")+COUNTIF(F78:AI78,"1")) | D78: =IF(A78="","",IF(C78>2*COUNTA(F$73:AI$73)/3,1,IF(C78>=COUNTA(F$73:AI$73)/2,0.8,0.5))) | E78: =IF(A78="","",SUMIFS('Логи'!$H$4:$H$3006,'Логи'!$A$4:$A$3006,A78,'Логи'!$C$4:$C$3006,2))
A79: Студент1.6 | C79: =IF(A79="","",COUNTIF(F79:AI79,"+")+COUNTIF(F79:AI79,"1")) | D79: =IF(A79="","",IF(C79>2*COUNTA(F$73:AI$73)/3,1,IF(C79>=COUNTA(F$73:AI$73)/2,0.8,0.5))) | E79: =IF(A79="","",SUMIFS('Логи'!$H$4:$H$3006,'Логи'!$A$4:$A$3006,A79,'Логи'!$C$4:$C$3006,2))
A80: Студент1.7 | C80: =IF(A80="","",COUNTIF(F80:AI80,"+")+COUNTIF(F80:AI80,"1")) | D80: =IF(A80="","",IF(C80>2*COUNTA(F$73:AI$73)/3,1,IF(C80>=COUNTA(F$73:AI$73)/2,0.8,0.5))) | E80: =IF(A80="","",SUMIFS('Логи'!$H$4:$H$3006,'Логи'!$A$4:$A$3006,A80,'Логи'!$C$4:$C$3006,2))
A81: Студент1.8 | C81: =IF(A81="","",COUNTIF(F81:AI81,"+")+COUNTIF(F81:AI81,"1")) | D81: =IF(A81="","",IF(C81>2*COUNTA(F$73:AI$73)/3,1,IF(C81>=COUNTA(F$73:AI$73)/2,0.8,0.5))) | E81: =IF(A81="","",SUMIFS('Логи'!$H$4:$H$3006,'Логи'!$A$4:$A$3006,A81,'Логи'!$C$4:$C$3006,2))
...

Sheet Плюсы_Рами
A1: Плюсы — Рами
A4: Практика 1 — плюсы
A5: Имя | B5: TG | C5: S | D5: Коэффициент | E5: D за практику | F5: 1.0 | G5: 2.0 | H5: 3.0 | I5: 4.0 | J5: 5.0 | K5: 6 | L5: 7 | M5: 8 | N5: 9 | O5: 10 | P5: 11 | Q5: 12 | R5: 13 | S5: 14 | T5: 15 | U5: 16 | V5: 17 | W5: 18 | X5: 19 | Y5: 20 | Z5: 21 | AA5: 22 | AB5: 23 | AC5: 24 | AD5: 25 | AE5: 26 | AF5: 27 | AG5: 28 | AH5: 29 | AI5: 30
A6: Студент2.1 | C6: =IF(A6="","",COUNTIF(F6:AI6,"+")+COUNTIF(F6:AI6,"1")) | D6: =IF(A6="","",IF(C6>2*COUNTA(F$5:AI$5)/3,1,IF(C6>=COUNTA(F$5:AI$5)/2,0.8,0.5))) | E6: =IF(A6="","",SUMIFS('Логи'!$H$4:$H$3006,'Логи'!$A$4:$A$3006,A6,'Логи'!$C$4:$C$3006,1))
A7: Студент2.2 | C7: =IF(A7="","",COUNTIF(F7:AI7,"+")+COUNTIF(F7:AI7,"1")) | D7: =IF(A7="","",IF(C7>2*COUNTA(F$5:AI$5)/3,1,IF(C7>=COUNTA(F$5:AI$5)/2,0.8,0.5))) | E7: =IF(A7="","",SUMIFS('Логи'!$H$4:$H$3006,'Логи'!$A$4:$A$3006,A7,'Логи'!$C$4:$C$3006,1))
A8: Студент2.3 | C8: =IF(A8="","",COUNTIF(F8:AI8,"+")+COUNTIF(F8:AI8,"1")) | D8: =IF(A8="","",IF(C8>2*COUNTA(F$5:AI$5)/3,1,IF(C8>=COUNTA(F$5:AI$5)/2,0.8,0.5))) | E8: =IF(A8="","",SUMIFS('Логи'!$H$4:$H$3006,'Логи'!$A$4:$A$3006,A8,'Логи'!$C$4:$C$3006,1))
A9: Студент2.4 | C9: =IF(A9="","",COUNTIF(F9:AI9,"+")+COUNTIF(F9:AI9,"1")) | D9: =IF(A9="","",IF(C9>2*COUNTA(F$5:AI$5)/3,1,IF(C9>=COUNTA(F$5:AI$5)/2,0.8,0.5))) | E9: =IF(A9="","",SUMIFS('Логи'!$H$4:$H$3006,'Логи'!$A$4:$A$3006,A9,'Логи'!$C$4:$C$3006,1))
A10: Студент2.5 | C10: =IF(A10="","",COUNTIF(F10:AI10,"+")+COUNTIF(F10:AI10,"1")) | D10: =IF(A10="","",IF(C10>2*COUNTA(F$5:AI$5)/3,1,IF(C10>=COUNTA(F$5:AI$5)/2,0.8,0.5))) | E10: =IF(A10="","",SUMIFS('Логи'!$H$4:$H$3006,'Логи'!$A$4:$A$3006,A10,'Логи'!$C$4:$C$3006,1))
A11: Студент2.6 | C11: =IF(A11="","",COUNTIF(F11:AI11,"+")+COUNTIF(F11:AI11,"1")) | D11: =IF(A11="","",IF(C11>2*COUNTA(F$5:AI$5)/3,1,IF(C11>=COUNTA(F$5:AI$5)/2,0.8,0.5))) | E11: =IF(A11="","",SUMIFS('Логи'!$H$4:$H$3006,'Логи'!$A$4:$A$3006,A11,'Логи'!$C$4:$C$3006,1))
A12: Студент2.7 | C12: =IF(A12="","",COUNTIF(F12:AI12,"+")+COUNTIF(F12:AI12,"1")) | D12: =IF(A12="","",IF(C12>2*COUNTA(F$5:AI$5)/3,1,IF(C12>=COUNTA(F$5:AI$5)/2,0.8,0.5))) | E12: =IF(A12="","",SUMIFS('Логи'!$H$4:$H$3006,'Логи'!$A$4:$A$3006,A12,'Логи'!$C$4:$C$3006,1))
A13: Студент2.8 | C13: =IF(A13="","",COUNTIF(F13:AI13,"+")+COUNTIF(F13:AI13,"1")) | D13: =IF(A13="","",IF(C13>2*COUNTA(F$5:AI$5)/3,1,IF(C13>=COUNTA(F$5:AI$5)/2,0.8,0.5))) | E13: =IF(A13="","",SUMIFS('Логи'!$H$4:$H$3006,'Логи'!$A$4:$A$3006,A13,'Логи'!$C$4:$C$3006,1))
A14: Студент2.9 | C14: =IF(A14="","",COUNTIF(F14:AI14,"+")+COUNTIF(F14:AI14,"1")) | D14: =IF(A14="","",IF(C14>2*COUNTA(F$5:AI$5)/3,1,IF(C14>=COUNTA(F$5:AI$5)/2,0.8,0.5))) | E14: =IF(A14="","",SUMIFS('Логи'!$H$4:$H$3006,'Логи'!$A$4:$A$3006,A14,'Логи'!$C$4:$C$3006,1))
A15: Студент2.10 | C15: =IF(A15="","",COUNTIF(F15:AI15,"+")+COUNTIF(F15:AI15,"1")) | D15: =IF(A15="","",IF(C15>2*COUNTA(F$5:AI$5)/3,1,IF(C15>=COUNTA(F$5:AI$5)/2,0.8,0.5))) | E15: =IF(A15="","",SUMIFS('Логи'!$H$4:$H$3006,'Логи'!$A$4:$A$3006,A15,'Логи'!$C$4:$C$3006,1))
A16: Студент2.11 | C16: =IF(A16="","",COUNTIF(F16:AI16,"+")+COUNTIF(F16:AI16,"1")) | D16: =IF(A16="","",IF(C16>2*COUNTA(F$5:AI$5)/3,1,IF(C16>=COUNTA(F$5:AI$5)/2,0.8,0.5))) | E16: =IF(A16="","",SUMIFS('Логи'!$H$4:$H$3006,'Логи'!$A$4:$A$3006,A16,'Логи'!$C$4:$C$3006,1))
A17: Студент2.12 | C17: =IF(A17="","",COUNTIF(F17:AI17,"+")+COUNTIF(F17:AI17,"1")) | D17: =IF(A17="","",IF(C17>2*COUNTA(F$5:AI$5)/3,1,IF(C17>=COUNTA(F$5:AI$5)/2,0.8,0.5))) | E17: =IF(A17="","",SUMIFS('Логи'!$H$4:$H$3006,'Логи'!$A$4:$A$3006,A17,'Логи'!$C$4:$C$3006,1))
... A35: Студент2.30 | C35: =IF(A35="","",COUNTIF(F35:AI35,"+")+COUNTIF(F35:AI35,"1")) | D35: =IF(A35="","",IF(C35>2*COUNTA(F$5:AI$5)/3,1,IF(C35>=COUNTA(F$5:AI$5)/2,0.8,0.5))) | E35: =IF(A35="","",SUMIFS('Логи'!$H$4:$H$3006,'Логи'!$A$4:$A$3006,A35,'Логи'!$C$4:$C$3006,1))
A37: Практика 1 — результаты рассказа
A38: Имя | B38: TG | F38: 1.0 | G38: 2.0 | H38: 3.0 | I38: 4.0 | J38: 5.0 | K38: 6 | L38: 7 | M38: 8 | N38: 9 | O38: 10 | P38: 11 | Q38: 12 | R38: 13 | S38: 14 | T38: 15 | U38: 16 | V38: 17 | W38: 18 | X38: 19 | Y38: 20 | Z38: 21 | AA38: 22 | AB38: 23 | AC38: 24 | AD38: 25 | AE38: 26 | AF38: 27 | AG38: 28 | AH38: 29 | AI38: 30
A39: Студент2.1
A40: Студент2.2
A41: Студент2.3
A42: Студент2.4
A43: Студент2.5
A44: Студент2.6
A45: Студент2.7
A46: Студент2.8
A47: Студент2.9
A48: Студент2.10
A49: Студент2.11
A50: Студент2.12
... A72: Практика 2 — плюсы
A73: Имя | B73: TG | C73: S | D73: Коэффициент | E73: D за практику | F73: 1.0 | G73: 2.0 | H73: 3.0 | I73: 4.0 | J73: 5.0 | K73: 6 | L73: 7 | M73: 8 | N73: 9 | O73: 10 | P73: 11 | Q73: 12 | R73: 13 | S73: 14 | T73: 15 | U73: 16 | V73: 17 | W73: 18 | X73: 19 | Y73: 20 | Z73: 21 | AA73: 22 | AB73: 23 | AC73: 24 | AD73: 25 | AE73: 26 | AF73: 27 | AG73: 28 | AH73: 29 | AI73: 30
A74: Студент2.1 | C74: =IF(A74="","",COUNTIF(F74:AI74,"+")+COUNTIF(F74:AI74,"1")) | D74: =IF(A74="","",IF(C74>2*COUNTA(F$73:AI$73)/3,1,IF(C74>=COUNTA(F$73:AI$73)/2,0.8,0.5))) | E74: =IF(A74="","",SUMIFS('Логи'!$H$4:$H$3006,'Логи'!$A$4:$A$3006,A74,'Логи'!$C$4:$C$3006,2))
A75: Студент2.2 | C75: =IF(A75="","",COUNTIF(F75:AI75,"+")+COUNTIF(F75:AI75,"1")) | D75: =IF(A75="","",IF(C75>2*COUNTA(F$73:AI$73)/3,1,IF(C75>=COUNTA(F$73:AI$73)/2,0.8,0.5))) | E75: =IF(A75="","",SUMIFS('Логи'!$H$4:$H$3006,'Логи'!$A$4:$A$3006,A75,'Логи'!$C$4:$C$3006,2))
A76: Студент2.3 | C76: =IF(A76="","",COUNTIF(F76:AI76,"+")+COUNTIF(F76:AI76,"1")) | D76: =IF(A76="","",IF(C76>2*COUNTA(F$73:AI$73)/3,1,IF(C76>=COUNTA(F$73:AI$73)/2,0.8,0.5))) | E76: =IF(A76="","",SUMIFS('Логи'!$H$4:$H$3006,'Логи'!$A$4:$A$3006,A76,'Логи'!$C$4:$C$3006,2))
A77: Студент2.4 | C77: =IF(A77="","",COUNTIF(F77:AI77,"+")+COUNTIF(F77:AI77,"1")) | D77: =IF(A77="","",IF(C77>2*COUNTA(F$73:AI$73)/3,1,IF(C77>=COUNTA(F$73:AI$73)/2,0.8,0.5))) | E77: =IF(A77="","",SUMIFS('Логи'!$H$4:$H$3006,'Логи'!$A$4:$A$3006,A77,'Логи'!$C$4:$C$3006,2))
A78: Студент2.5 | C78: =IF(A78="","",COUNTIF(F78:AI78,"+")+COUNTIF(F78:AI78,"1")) | D78: =IF(A78="","",IF(C78>2*COUNTA(F$73:AI$73)/3,1,IF(C78>=COUNTA(F$73:AI$73)/2,0.8,0.5))) | E78: =IF(A78="","",SUMIFS('Логи'!$H$4:$H$3006,'Логи'!$A$4:$A$3006,A78,'Логи'!$C$4:$C$3006,2))
A79: Студент2.6 | C79: =IF(A79="","",COUNTIF(F79:AI79,"+")+COUNTIF(F79:AI79,"1")) | D79: =IF(A79="","",IF(C79>2*COUNTA(F$73:AI$73)/3,1,IF(C79>=COUNTA(F$73:AI$73)/2,0.8,0.5))) | E79: =IF(A79="","",SUMIFS('Логи'!$H$4:$H$3006,'Логи'!$A$4:$A$3006,A79,'Логи'!$C$4:$C$3006,2))
A80: Студент2.7 | C80: =IF(A80="","",COUNTIF(F80:AI80,"+")+COUNTIF(F80:AI80,"1")) | D80: =IF(A80="","",IF(C80>2*COUNTA(F$73:AI$73)/3,1,IF(C80>=COUNTA(F$73:AI$73)/2,0.8,0.5))) | E80: =IF(A80="","",SUMIFS('Логи'!$H$4:$H$3006,'Логи'!$A$4:$A$3006,A80,'Логи'!$C$4:$C$3006,2))
A81: Студент2.8 | C81: =IF(A81="","",COUNTIF(F81:AI81,"+")+COUNTIF(F81:AI81,"1")) | D81: =IF(A81="","",IF(C81>2*COUNTA(F$73:AI$73)/3,1,IF(C81>=COUNTA(F$73:AI$73)/2,0.8,0.5))) | E81: =IF(A81="","",SUMIFS('Логи'!$H$4:$H$3006,'Логи'!$A$4:$A$3006,A81,'Логи'!$C$4:$C$3006,2))
...

Sheet Плюсы_Немат
A1: Плюсы — Немат
A4: Практика 1 — плюсы
A5: Имя | B5: TG | C5: S | D5: Коэффициент | E5: D за практику | F5: 1.0 | G5: 2.0 | H5: 3.0 | I5: 4.0 | J5: 5.0 | K5: 6 | L5: 7 | M5: 8 | N5: 9 | O5: 10 | P5: 11 | Q5: 12 | R5: 13 | S5: 14 | T5: 15 | U5: 16 | V5: 17 | W5: 18 | X5: 19 | Y5: 20 | Z5: 21 | AA5: 22 | AB5: 23 | AC5: 24 | AD5: 25 | AE5: 26 | AF5: 27 | AG5: 28 | AH5: 29 | AI5: 30
A6: Студент3.1 | C6: =IF(A6="","",COUNTIF(F6:AI6,"+")+COUNTIF(F6:AI6,"1")) | D6: =IF(A6="","",IF(C6>2*COUNTA(F$5:AI$5)/3,1,IF(C6>=COUNTA(F$5:AI$5)/2,0.8,0.5))) | E6: =IF(A6="","",SUMIFS('Логи'!$H$4:$H$3006,'Логи'!$A$4:$A$3006,A6,'Логи'!$C$4:$C$3006,1))
A7: Студент3.2 | C7: =IF(A7="","",COUNTIF(F7:AI7,"+")+COUNTIF(F7:AI7,"1")) | D7: =IF(A7="","",IF(C7>2*COUNTA(F$5:AI$5)/3,1,IF(C7>=COUNTA(F$5:AI$5)/2,0.8,0.5))) | E7: =IF(A7="","",SUMIFS('Логи'!$H$4:$H$3006,'Логи'!$A$4:$A$3006,A7,'Логи'!$C$4:$C$3006,1))
A8: Студент3.3 | C8: =IF(A8="","",COUNTIF(F8:AI8,"+")+COUNTIF(F8:AI8,"1")) | D8: =IF(A8="","",IF(C8>2*COUNTA(F$5:AI$5)/3,1,IF(C8>=COUNTA(F$5:AI$5)/2,0.8,0.5))) | E8: =IF(A8="","",SUMIFS('Логи'!$H$4:$H$3006,'Логи'!$A$4:$A$3006,A8,'Логи'!$C$4:$C$3006,1))
A9: Студент3.4 | C9: =IF(A9="","",COUNTIF(F9:AI9,"+")+COUNTIF(F9:AI9,"1")) | D9: =IF(A9="","",IF(C9>2*COUNTA(F$5:AI$5)/3,1,IF(C9>=COUNTA(F$5:AI$5)/2,0.8,0.5))) | E9: =IF(A9="","",SUMIFS('Логи'!$H$4:$H$3006,'Логи'!$A$4:$A$3006,A9,'Логи'!$C$4:$C$3006,1))
A10: Студент3.5 | C10: =IF(A10="","",COUNTIF(F10:AI10,"+")+COUNTIF(F10:AI10,"1")) | D10: =IF(A10="","",IF(C10>2*COUNTA(F$5:AI$5)/3,1,IF(C10>=COUNTA(F$5:AI$5)/2,0.8,0.5))) | E10: =IF(A10="","",SUMIFS('Логи'!$H$4:$H$3006,'Логи'!$A$4:$A$3006,A10,'Логи'!$C$4:$C$3006,1))
A11: Студент3.6 | C11: =IF(A11="","",COUNTIF(F11:AI11,"+")+COUNTIF(F11:AI11,"1")) | D11: =IF(A11="","",IF(C11>2*COUNTA(F$5:AI$5)/3,1,IF(C11>=COUNTA(F$5:AI$5)/2,0.8,0.5))) | E11: =IF(A11="","",SUMIFS('Логи'!$H$4:$H$3006,'Логи'!$A$4:$A$3006,A11,'Логи'!$C$4:$C$3006,1))
A12: Студент3.7 | C12: =IF(A12="","",COUNTIF(F12:AI12,"+")+COUNTIF(F12:AI12,"1")) | D12: =IF(A12="","",IF(C12>2*COUNTA(F$5:AI$5)/3,1,IF(C12>=COUNTA(F$5:AI$5)/2,0.8,0.5))) | E12: =IF(A12="","",SUMIFS('Логи'!$H$4:$H$3006,'Логи'!$A$4:$A$3006,A12,'Логи'!$C$4:$C$3006,1))
A13: Студент3.8 | C13: =IF(A13="","",COUNTIF(F13:AI13,"+")+COUNTIF(F13:AI13,"1")) | D13: =IF(A13="","",IF(C13>2*COUNTA(F$5:AI$5)/3,1,IF(C13>=COUNTA(F$5:AI$5)/2,0.8,0.5))) | E13: =IF(A13="","",SUMIFS('Логи'!$H$4:$H$3006,'Логи'!$A$4:$A$3006,A13,'Логи'!$C$4:$C$3006,1))
A14: Студент3.9 | C14: =IF(A14="","",COUNTIF(F14:AI14,"+")+COUNTIF(F14:AI14,"1")) | D14: =IF(A14="","",IF(C14>2*COUNTA(F$5:AI$5)/3,1,IF(C14>=COUNTA(F$5:AI$5)/2,0.8,0.5))) | E14: =IF(A14="","",SUMIFS('Логи'!$H$4:$H$3006,'Логи'!$A$4:$A$3006,A14,'Логи'!$C$4:$C$3006,1))
A15: Студент3.10 | C15: =IF(A15="","",COUNTIF(F15:AI15,"+")+COUNTIF(F15:AI15,"1")) | D15: =IF(A15="","",IF(C15>2*COUNTA(F$5:AI$5)/3,1,IF(C15>=COUNTA(F$5:AI$5)/2,0.8,0.5))) | E15: =IF(A15="","",SUMIFS('Логи'!$H$4:$H$3006,'Логи'!$A$4:$A$3006,A15,'Логи'!$C$4:$C$3006,1))
A16: Студент3.11 | C16: =IF(A16="","",COUNTIF(F16:AI16,"+")+COUNTIF(F16:AI16,"1")) | D16: =IF(A16="","",IF(C16>2*COUNTA(F$5:AI$5)/3,1,IF(C16>=COUNTA(F$5:AI$5)/2,0.8,0.5))) | E16: =IF(A16="","",SUMIFS('Логи'!$H$4:$H$3006,'Логи'!$A$4:$A$3006,A16,'Логи'!$C$4:$C$3006,1))
A17: Студент3.12 | C17: =IF(A17="","",COUNTIF(F17:AI17,"+")+COUNTIF(F17:AI17,"1")) | D17: =IF(A17="","",IF(C17>2*COUNTA(F$5:AI$5)/3,1,IF(C17>=COUNTA(F$5:AI$5)/2,0.8,0.5))) | E17: =IF(A17="","",SUMIFS('Логи'!$H$4:$H$3006,'Логи'!$A$4:$A$3006,A17,'Логи'!$C$4:$C$3006,1))
... A35: Студент3.30 | C35: =IF(A35="","",COUNTIF(F35:AI35,"+")+COUNTIF(F35:AI35,"1")) | D35: =IF(A35="","",IF(C35>2*COUNTA(F$5:AI$5)/3,1,IF(C35>=COUNTA(F$5:AI$5)/2,0.8,0.5))) | E35: =IF(A35="","",SUMIFS('Логи'!$H$4:$H$3006,'Логи'!$A$4:$A$3006,A35,'Логи'!$C$4:$C$3006,1))
A37: Практика 1 — результаты рассказа
A38: Имя | B38: TG | F38: 1.0 | G38: 2.0 | H38: 3.0 | I38: 4.0 | J38: 5.0 | K38: 6 | L38: 7 | M38: 8 | N38: 9 | O38: 10 | P38: 11 | Q38: 12 | R38: 13 | S38: 14 | T38: 15 | U38: 16 | V38: 17 | W38: 18 | X38: 19 | Y38: 20 | Z38: 21 | AA38: 22 | AB38: 23 | AC38: 24 | AD38: 25 | AE38: 26 | AF38: 27 | AG38: 28 | AH38: 29 | AI38: 30
A39: Студент3.1
A40: Студент3.2
A41: Студент3.3
A42: Студент3.4
A43: Студент3.5
A44: Студент3.6
A45: Студент3.7
A46: Студент3.8
A47: Студент3.9
A48: Студент3.10
A49: Студент3.11
A50: Студент3.12
... A72: Практика 2 — плюсы
A73: Имя | B73: TG | C73: S | D73: Коэффициент | E73: D за практику | F73: 1.0 | G73: 2.0 | H73: 3.0 | I73: 4.0 | J73: 5.0 | K73: 6 | L73: 7 | M73: 8 | N73: 9 | O73: 10 | P73: 11 | Q73: 12 | R73: 13 | S73: 14 | T73: 15 | U73: 16 | V73: 17 | W73: 18 | X73: 19 | Y73: 20 | Z73: 21 | AA73: 22 | AB73: 23 | AC73: 24 | AD73: 25 | AE73: 26 | AF73: 27 | AG73: 28 | AH73: 29 | AI73: 30
A74: Студент3.1 | C74: =IF(A74="","",COUNTIF(F74:AI74,"+")+COUNTIF(F74:AI74,"1")) | D74: =IF(A74="","",IF(C74>2*COUNTA(F$73:AI$73)/3,1,IF(C74>=COUNTA(F$73:AI$73)/2,0.8,0.5))) | E74: =IF(A74="","",SUMIFS('Логи'!$H$4:$H$3006,'Логи'!$A$4:$A$3006,A74,'Логи'!$C$4:$C$3006,2))
A75: Студент3.2 | C75: =IF(A75="","",COUNTIF(F75:AI75,"+")+COUNTIF(F75:AI75,"1")) | D75: =IF(A75="","",IF(C75>2*COUNTA(F$73:AI$73)/3,1,IF(C75>=COUNTA(F$73:AI$73)/2,0.8,0.5))) | E75: =IF(A75="","",SUMIFS('Логи'!$H$4:$H$3006,'Логи'!$A$4:$A$3006,A75,'Логи'!$C$4:$C$3006,2))
A76: Студент3.3 | C76: =IF(A76="","",COUNTIF(F76:AI76,"+")+COUNTIF(F76:AI76,"1")) | D76: =IF(A76="","",IF(C76>2*COUNTA(F$73:AI$73)/3,1,IF(C76>=COUNTA(F$73:AI$73)/2,0.8,0.5))) | E76: =IF(A76="","",SUMIFS('Логи'!$H$4:$H$3006,'Логи'!$A$4:$A$3006,A76,'Логи'!$C$4:$C$3006,2))
A77: Студент3.4 | C77: =IF(A77="","",COUNTIF(F77:AI77,"+")+COUNTIF(F77:AI77,"1")) | D77: =IF(A77="","",IF(C77>2*COUNTA(F$73:AI$73)/3,1,IF(C77>=COUNTA(F$73:AI$73)/2,0.8,0.5))) | E77: =IF(A77="","",SUMIFS('Логи'!$H$4:$H$3006,'Логи'!$A$4:$A$3006,A77,'Логи'!$C$4:$C$3006,2))
A78: Студент3.5 | C78: =IF(A78="","",COUNTIF(F78:AI78,"+")+COUNTIF(F78:AI78,"1")) | D78: =IF(A78="","",IF(C78>2*COUNTA(F$73:AI$73)/3,1,IF(C78>=COUNTA(F$73:AI$73)/2,0.8,0.5))) | E78: =IF(A78="","",SUMIFS('Логи'!$H$4:$H$3006,'Логи'!$A$4:$A$3006,A78,'Логи'!$C$4:$C$3006,2))
A79: Студент3.6 | C79: =IF(A79="","",COUNTIF(F79:AI79,"+")+COUNTIF(F79:AI79,"1")) | D79: =IF(A79="","",IF(C79>2*COUNTA(F$73:AI$73)/3,1,IF(C79>=COUNTA(F$73:AI$73)/2,0.8,0.5))) | E79: =IF(A79="","",SUMIFS('Логи'!$H$4:$H$3006,'Логи'!$A$4:$A$3006,A79,'Логи'!$C$4:$C$3006,2))
A80: Студент3.7 | C80: =IF(A80="","",COUNTIF(F80:AI80,"+")+COUNTIF(F80:AI80,"1")) | D80: =IF(A80="","",IF(C80>2*COUNTA(F$73:AI$73)/3,1,IF(C80>=COUNTA(F$73:AI$73)/2,0.8,0.5))) | E80: =IF(A80="","",SUMIFS('Логи'!$H$4:$H$3006,'Логи'!$A$4:$A$3006,A80,'Логи'!$C$4:$C$3006,2))
A81: Студент3.8 | C81: =IF(A81="","",COUNTIF(F81:AI81,"+")+COUNTIF(F81:AI81,"1")) | D81: =IF(A81="","",IF(C81>2*COUNTA(F$73:AI$73)/3,1,IF(C81>=COUNTA(F$73:AI$73)/2,0.8,0.5))) | E81: =IF(A81="","",SUMIFS('Логи'!$H$4:$H$3006,'Логи'!$A$4:$A$3006,A81,'Логи'!$C$4:$C$3006,2))
...
